id: PYSEC-0000-CVE-2023-29824
details: '** DISPUTED ** A use-after-free issue was discovered in Py_FindObjects()
  function in SciPy versions prior to 1.8.0. NOTE: the vendor and discoverer indicate
  that this is not a security issue.'
affected:
- package:
    name: scipy
    ecosystem: PyPI
    purl: pkg:pypi/scipy
  ranges:
  - type: ECOSYSTEM
    events:
    - introduced: "0"
    - fixed: 1.8.0
references:
- type: EVIDENCE
  url: https://github.com/scipy/scipy/issues/14713
- type: REPORT
  url: https://github.com/scipy/scipy/issues/14713
- type: WEB
  url: http://www.square16.org/achievement/cve-2023-29824/
- type: FIX
  url: https://github.com/scipy/scipy/pull/15013
- type: EVIDENCE
  url: https://github.com/scipy/scipy/issues/14713#issuecomment-1629468565
- type: REPORT
  url: https://github.com/scipy/scipy/issues/14713#issuecomment-1629468565
aliases:
- CVE-2023-29824
modified: "2023-07-17T18:51:00Z"
published: "2023-07-06T21:15:00Z"
