id: PYSEC-0000-CVE-2023-26151
severity:
- type: CVSS_V3
  score: CVSS:3.1/AV:N/AC:L/PR:N/UI:N/S:U/C:N/I:N/A:H
details: Versions of the package asyncua before 0.9.96 are vulnerable to Denial of
  Service (DoS) such that an attacker can send a malformed packet and as a result,
  the server will enter into an infinite loop and consume excessive memory.
affected:
- package:
    name: asyncua
    ecosystem: PyPI
    purl: pkg:pypi/asyncua
  ranges:
  - type: GIT
    repo: https://github.com/FreeOpcUa/opcua-asyncio
    events:
    - introduced: "0"
    - fixed: f6603daa34a93a658f0e176cb0b9ee5a6643b262
  - type: ECOSYSTEM
    events:
    - introduced: "0"
    - fixed: 0.9.96
references:
- type: EVIDENCE
  url: https://gist.github.com/artfire52/1540b234350795e0ecb4d672608dbec8
- type: WEB
  url: https://gist.github.com/artfire52/1540b234350795e0ecb4d672608dbec8
- type: WEB
  url: https://github.com/FreeOpcUa/opcua-asyncio/releases/tag/v0.9.96
- type: EVIDENCE
  url: https://security.snyk.io/vuln/SNYK-PYTHON-ASYNCUA-5673709
- type: FIX
  url: https://security.snyk.io/vuln/SNYK-PYTHON-ASYNCUA-5673709
- type: WEB
  url: https://security.snyk.io/vuln/SNYK-PYTHON-ASYNCUA-5673709
- type: EVIDENCE
  url: https://github.com/FreeOpcUa/opcua-asyncio/issues/1013
- type: REPORT
  url: https://github.com/FreeOpcUa/opcua-asyncio/issues/1013
- type: FIX
  url: https://github.com/FreeOpcUa/opcua-asyncio/pull/1039
- type: FIX
  url: https://github.com/FreeOpcUa/opcua-asyncio/commit/f6603daa34a93a658f0e176cb0b9ee5a6643b262
aliases:
- CVE-2023-26151
modified: "2023-10-04T17:12:00Z"
published: "2023-10-03T05:15:00Z"
